const err = new Error('Erro!')
try {
    console.log(f)
} catch (error) {
    throw err
}